Workbook

Sheet users_details
A1: UserID | B1: First Name | C1: Last Name | D1: Full Name | E1: Age | F1: Address | G1: Neighbourhood
A2: 6117666160 | B2: Robert | C2: Johnson | D2: =_xlfn.CONCAT(B2, " ", C2) -> Robert Johnson | E2: 53 | F2: Williamsburg, Brooklyn | G2: Williamsburg
A3: 1644430081 | B3: John | C3: Brown | D3: =_xlfn.CONCAT(B3, " ", C3) -> John Brown | E3: 56 | F3: Flatbush, Brooklyn | G3: Flatbush
A4: 1927972279 | B4: Michael | C4: Brown | D4: =_xlfn.CONCAT(B4, " ", C4) -> Michael Brown | E4: 29 | F4: Crown Heights, Brooklyn | G4: Crown Heights
A5: 4388161847 | B5: Michael | C5: Brown | D5: =_xlfn.CONCAT(B5, " ", C5) -> Michael Brown | E5: 36 | F5: Williamsburg, Brooklyn | G5: Williamsburg
A6: 6775888955 | B6: David | C6: Davis | D6: =_xlfn.CONCAT(B6, " ", C6) -> David Davis | E6: 45 | F6: Harlem, Manhattan | G6: Harlem
A7: 4319703577 | B7: James | C7: Smith | D7: =_xlfn.CONCAT(B7, " ", C7) -> James Smith | E7: 18 | F7: Upper West Side, Manhattan | G7: Upper West Side
A8: 2873212765 | B8: Michael | C8: Johnson | D8: =_xlfn.CONCAT(B8, " ", C8) -> Michael Johnson | E8: 32 | F8: Greenpoint, Brooklyn | G8: Greenpoint
A9: 4445114986 | B9: Robert | C9: Martinez | D9: =_xlfn.CONCAT(B9, " ", C9) -> Robert Martinez | E9: 53 | F9: Harlem, Manhattan | G9: Harlem
A10: 6290855005 | B10: Mary | C10: Martinez | D10: =_xlfn.CONCAT(B10, " ", C10) -> Mary Martinez | E10: 30 | F10: Midtown, Manhattan | G10: Midtown
A11: 3977333714 | B11: Alice | C11: Smith | D11: =_xlfn.CONCAT(B11, " ", C11) -> Alice Smith | E11: 60 | F11: East Village, Manhattan | G11: East Village
A12: 1503960366 | B12: David | C12: Jones | D12: =_xlfn.CONCAT(B12, " ", C12) -> David Jones | E12: 38 | F12: East Harlem, Manhattan | G12: East Harlem
A13: 4558609924 | B13: Patricia | C13: Davis | D13: =_xlfn.CONCAT(B13, " ", C13) -> Patricia Davis | E13: 29 | F13: East Village, Manhattan | G13: East Village
... A34: 5553957443 | B34: Linda | C34: Martinez | D34: =_xlfn.CONCAT(B34, " ", C34) -> Linda Martinez | E34: 23 | F34: Washington Heights, Manhattan | G34: Washington Heights

Sheet activity
A1: UserID | B1: Date | C1: Total_Distance | D1: Tracker_Distance | E1: Logged_Activities_Distance | F1: Very_Active_Distance | G1: Moderately_Active_Distance | H1: Light_Active_Distance | I1: Sedentary_Active_Distance | J1: Very_Active_Minutes | K1: Fairly_Active_Minutes | L1: Lightly_Active_Minutes | M1: Sedentary_Minutes | N1: Steps | O1: Calories_Burned
A2: 6117666160 | B2: 42480 | C2: 8.0200005 | D2: 8.0200005 | E2: 0 | F2: 2.03 | G2: 0.47999999 | H2: 5.52 | I2: 0 | J2: 26 | K2: 10 | L2: 349 | M2: 587 | N2: 10449 | O2: 2536
A3: 1644430081 | B3: 42473 | C3: 5.8200002 | D3: 5.8200002 | E3: 0 | F3: 2.28 | G3: 0.89999998 | H3: 2.6400001 | I3: 0 | J3: 30 | K3: 16 | L3: 135 | M3: 1259 | N3: 8001 | O3: 2902
A4: 1927972279 | B4: 42485 | C4: 0.11 | D4: 0.11 | E4: 0 | F4: 0 | G4: 0 | H4: 0.11 | I4: 0 | J4: 0 | K4: 0 | L4: 12 | M4: 1303 | N4: 152 | O4: 2100
A5: 6117666160 | B5: 42486 | C5: 7.21 | D5: 7.21 | E5: 0 | F5: 0 | G5: 0.34 | H5: 6.8699999 | I5: 0 | J5: 0 | K5: 7 | L5: 352 | M5: 1077 | N5: 9543 | O5: 2450
A6: 4388161847 | B6: 42618 | C6: 7.8600001 | D6: 7.8600001 | E6: 0 | F6: 0.34 | G6: 0.73000002 | H6: 6.79 | I6: 0 | J6: 6 | K6: 19 | L6: 258 | M6: 1020 | N6: 10218 | O6: 3013
A7: 6775888955 | B7: 42488 | C7: 0.5 | D7: 0.5 | E7: 0 | F7: 0.059999999 | G7: 0.2 | H7: 0.23999999 | I7: 0 | J7: 2 | K7: 13 | L7: 15 | M7: 1410 | N7: 703 | O7: 1993
A8: 4319703577 | B8: 42473 | C8: 5.5 | D8: 5.5 | E8: 0 | F8: 0.52999997 | G8: 0.58999997 | H8: 1.3099999 | I8: 0 | J8: 8 | K8: 15 | L8: 96 | M8: 1234 | N8: 8204 | O8: 2135
A9: 2873212765 | B9: 42434 | C9: 4.98 | D9: 4.98 | E9: 0 | F9: 0.059999999 | G9: 0.25 | H9: 4.6599998 | I9: 0.01 | J9: 1 | K9: 6 | L9: 363 | M9: 1070 | N9: 7412 | O9: 1906
A10: 4445114986 | B10: 42473 | C10: 1.99 | D10: 1.99 | E10: 0 | F10: 0 | G10: 0 | H10: 1.99 | I10: 0 | J10: 0 | K10: 0 | L10: 194 | M10: 840 | N10: 2961 | O10: 2095
A11: 6290855005 | B11: 42587 | C11: 5.8299999 | D11: 5.8299999 | E11: 0 | F11: 0 | G11: 0 | H11: 5.8200002 | I11: 0 | J11: 0 | K11: 0 | L11: 251 | M11: 1189 | N11: 7706 | O11: 2712
A12: 3977333714 | B12: 42490 | C12: 9.1999998 | D12: 9.1999998 | E12: 0 | F12: 3.6900001 | G12: 2.0999999 | H12: 3.4100001 | I12: 0 | J12: 43 | K12: 52 | L12: 194 | M12: 687 | N12: 13238 | O12: 1650
A13: 1503960366 | B13: 42495 | C13: 8.8999996 | D13: 8.8999996 | E13: 0 | F13: 2.9200001 | G13: 1.08 | H13: 4.8800001 | I13: 0 | J13: 45 | K13: 24 | L13: 250 | M13: 857 | N13: 14070 | O13: 1959
... A941: 1844505072 | B941: 42482 | C941: 3.55 | D941: 3.55 | E941: 0 | F941: 0 | G941: 0 | H941: 3.55 | I941: 0 | J941: 0 | K941: 0 | L941: 220 | M941: 1220 | N941: 5372 | O941: 1827

Sheet user_activity
A1: UserID | B1: User Name | C1: Age | D1: Age Group | E1: Address | F1: Neighbourhood | G1: City | H1: Date | I1: Weekday_Name | J1: Month | K1: Total_Distance | L1: Tracker_Distance | M1: Logged_Activities_Distance | N1: Very_Active_Distance | O1: Moderately_Active_Distance | P1: Light_Active_Distance | Q1: Sedentary_Active_Distance | R1: Very_Active_Minutes | S1: Fairly_Active_Minutes | T1: Lightly_Active_Minutes | U1: Total_Active_Minutes | V1: Sedentary_Minutes | W1: Steps | X1: Steps_MedFill | Y1: Calories_Burned | Z1: Engagement Type | AA1: Calories_Per_Step
A2: 4319703577 | B2: James Smith | C2: =VLOOKUP(user_activity!A8,users_details!$A$1:$G$34,5,0) -> 18 | D2: {=_xlfn.IFS( AND(C2>=18, C2<=25), "Emerging Adults", AND(C2>=26, C2<=35), "Young Adults", AND(C2>=36, C2<=45), "Midlife Adults", AND(C2>=46, C2<=55), "Mature Adults", C2>=56, "Older Adults", TRUE, "Age Not Mentioned")} -> Emerging Adults | E2: =VLOOKUP(user_activity!A8,users_details!$A$1:$G$34,6,0) -> Hell's Kitchen, Manhattan | F2: =VLOOKUP(user_activity!A8,users_details!$A$1:$G$34,7,0) -> Hell's Kitchen | G2: Manhattan | H2: 42473 | I2: =TEXT(H2, "dddd") -> Wednesday | J2: =TEXT(H2, "mmmm") -> April | K2: 5.5 | L2: 5.5 | M2: 0 | N2: 0.52999997 | O2: 0.58999997 | P2: 1.3099999 | Q2: 0 | R2: 8 | S2: 15 | T2: 96 | U2: =R2+S2+T2 -> 119 | V2: 1234 | W2: 8204 | X2: =IF(W2=0,MEDIAN($W$2:$W$941),W2) -> 8204 | Y2: 2135 | Z2: {=_xlfn.IFS(OR(R2>66, S2>38), "High Engagement", OR(AND(R2>32, R2<=66), AND(S2>19, S2<=38)), "Medium-High Engagement", OR(AND(R2>4, R2<=32), AND(S2>6, S2<=19)),"Medium Engagement", TRUE, "Low Engagement" )} -> Medium Engagement | AA2: =IF(W2>0, Y2/W2, 0) -> 0.26023891 | AC2: =MEDIAN(W2:W941) -> 7405.5
A3: 2320127002 | B3: Mary Davis | C3: =VLOOKUP(user_activity!A79,users_details!$A$1:$G$34,5,0) -> 21 | D3: {=_xlfn.IFS( AND(C3>=18, C3<=25), "Emerging Adults", AND(C3>=26, C3<=35), "Young Adults", AND(C3>=36, C3<=45), "Midlife Adults", AND(C3>=46, C3<=55), "Mature Adults", C3>=56, "Older Adults", TRUE, "Age Not Mentioned")} -> Emerging Adults | E3: =VLOOKUP(user_activity!A79,users_details!$A$1:$G$34,6,0) -> Bushwick, Brooklyn | F3: =VLOOKUP(user_activity!A79,users_details!$A$1:$G$34,7,0) -> Bushwick | G3: Manhattan | H3: 42495 | I3: =TEXT(H3, "dddd") -> Thursday | J3: =TEXT(H3, "mmmm") -> May | K3: 3.51 | L3: 3.51 | M3: 0 | N3: 0 | O3: 0.38999999 | P3: 3.1099999 | Q3: 0 | R3: 0 | S3: 11 | T3: 223 | U3: =R3+S3+T3 -> 234 | V3: 1206 | W3: 5202 | X3: =IF(W3=0,MEDIAN($W$2:$W$941),W3) -> 5202 | Y3: 1780 | Z3: {=_xlfn.IFS(OR(R3>66, S3>38), "High Engagement", OR(AND(R3>32, R3<=66), AND(S3>19, S3<=38)), "Medium-High Engagement", OR(AND(R3>4, R3<=32), AND(S3>6, S3<=19)),"Medium Engagement", TRUE, "Low Engagement" )} -> Medium Engagement | AA3: =IF(W3>0, Y3/W3, 0) -> 0.34217609 | AC3: 7405.5
A4: 2320127002 | B4: Mary Davis | C4: =VLOOKUP(user_activity!A88,users_details!$A$1:$G$34,5,0) -> 21 | D4: {=_xlfn.IFS( AND(C4>=18, C4<=25), "Emerging Adults", AND(C4>=26, C4<=35), "Young Adults", AND(C4>=36, C4<=45), "Midlife Adults", AND(C4>=46, C4<=55), "Mature Adults", C4>=56, "Older Adults", TRUE, "Age Not Mentioned")} -> Emerging Adults | E4: =VLOOKUP(user_activity!A88,users_details!$A$1:$G$34,6,0) -> Bushwick, Brooklyn | F4: =VLOOKUP(user_activity!A88,users_details!$A$1:$G$34,7,0) -> Bushwick | G4: Manhattan | H4: 42374 | I4: =TEXT(H4, "dddd") -> Tuesday | J4: =TEXT(H4, "mmmm") -> January | K4: 0.51999998 | L4: 0.51999998 | M4: 0 | N4: 0 | O4: 0 | P4: 0.51999998 | Q4: 0 | R4: 0 | S4: 0 | T4: 40 | U4: =R4+S4+T4 -> 40 | V4: 1400 | W4: 772 | X4: =IF(W4=0,MEDIAN($W$2:$W$941),W4) -> 772 | Y4: 1403 | Z4: {=_xlfn.IFS(OR(R4>66, S4>38), "High Engagement", OR(AND(R4>32, R4<=66), AND(S4>19, S4<=38)), "Medium-High Engagement", OR(AND(R4>4, R4<=32), AND(S4>6, S4<=19)),"Medium Engagement", TRUE, "Low Engagement" )} -> Low Engagement | AA4: =IF(W4>0, Y4/W4, 0) -> 1.8173575
A5: 2320127002 | B5: Mary Davis | C5: =VLOOKUP(user_activity!A96,users_details!$A$1:$G$34,5,0) -> 22 | D5: {=_xlfn.IFS( AND(C5>=18, C5<=25), "Emerging Adults", AND(C5>=26, C5<=35), "Young Adults", AND(C5>=36, C5<=45), "Midlife Adults", AND(C5>=46, C5<=55), "Mature Adults", C5>=56, "Older Adults", TRUE, "Age Not Mentioned")} -> Emerging Adults | E5: =VLOOKUP(user_activity!A96,users_details!$A$1:$G$34,6,0) -> Upper East Side, Manhattan | F5: =VLOOKUP(user_activity!A96,users_details!$A$1:$G$34,7,0) -> Upper East Side | G5: Manhattan | H5: 42648 | I5: =TEXT(H5, "dddd") -> Wednesday | J5: =TEXT(H5, "mmmm") -> October | K5: 4.1999998 | L5: 4.1999998 | M5: 0 | N5: 0 | O5: 0 | P5: 4.1999998 | Q5: 0 | R5: 0 | S5: 0 | T5: 290 | U5: =R5+S5+T5 -> 290 | V5: 1150 | W5: 6227 | X5: =IF(W5=0,MEDIAN($W$2:$W$941),W5) -> 6227 | Y5: 1899 | Z5: {=_xlfn.IFS(OR(R5>66, S5>38), "High Engagement", OR(AND(R5>32, R5<=66), AND(S5>19, S5<=38)), "Medium-High Engagement", OR(AND(R5>4, R5<=32), AND(S5>6, S5<=19)),"Medium Engagement", TRUE, "Low Engagement" )} -> Low Engagement | AA5: =IF(W5>0, Y5/W5, 0) -> 0.30496226
A6: 4319703577 | B6: James Smith | C6: =VLOOKUP(user_activity!A117,users_details!$A$1:$G$34,5,0) -> 22 | D6: {=_xlfn.IFS( AND(C6>=18, C6<=25), "Emerging Adults", AND(C6>=26, C6<=35), "Young Adults", AND(C6>=36, C6<=45), "Midlife Adults", AND(C6>=46, C6<=55), "Mature Adults", C6>=56, "Older Adults", TRUE, "Age Not Mentioned")} -> Emerging Adults | E6: =VLOOKUP(user_activity!A117,users_details!$A$1:$G$34,6,0) -> Upper East Side, Manhattan | F6: =VLOOKUP(user_activity!A117,users_details!$A$1:$G$34,7,0) -> Upper East Side | G6: Manhattan | H6: 42495 | I6: =TEXT(H6, "dddd") -> Thursday | J6: =TEXT(H6, "mmmm") -> May | K6: 9.4899998 | L6: 9.4899998 | M6: 0 | N6: 2.6300001 | O6: 1.41 | P6: 5.4499998 | Q6: 0 | R6: 27 | S6: 34 | T6: 328 | U6: =R6+S6+T6 -> 389 | V6: 957 | W6: 13658 | X6: =IF(W6=0,MEDIAN($W$2:$W$941),W6) -> 13658 | Y6: 2530 | Z6: {=_xlfn.IFS(OR(R6>66, S6>38), "High Engagement", OR(AND(R6>32, R6<=66), AND(S6>19, S6<=38)), "Medium-High Engagement", OR(AND(R6>4, R6<=32), AND(S6>6, S6<=19)),"Medium Engagement", TRUE, "Low Engagement" )} -> Medium-High Engagement | AA6: =IF(W6>0, Y6/W6, 0) -> 0.18523942
A7: 4319703577 | B7: James Smith | C7: =VLOOKUP(user_activity!A144,users_details!$A$1:$G$34,5,0) -> 22 | D7: {=_xlfn.IFS( AND(C7>=18, C7<=25), "Emerging Adults", AND(C7>=26, C7<=35), "Young Adults", AND(C7>=36, C7<=45), "Midlife Adults", AND(C7>=46, C7<=55), "Mature Adults", C7>=56, "Older Adults", TRUE, "Age Not Mentioned")} -> Emerging Adults | E7: =VLOOKUP(user_activity!A144,users_details!$A$1:$G$34,6,0) -> Washington Heights, Manhattan | F7: =VLOOKUP(user_activity!A144,users_details!$A$1:$G$34,7,0) -> Washington Heights | G7: Manhattan | H7: 42485 | I7: =TEXT(H7, "dddd") -> Monday | J7: =TEXT(H7, "mmmm") -> April | K7: 6.21 | L7: 6.21 | M7: 0 | N7: 0 | O7: 0.28 | P7: 5.9299998 | Q7: 0 | R7: 0 | S7: 8 | T7: 390 | U7: =R7+S7+T7 -> 398 | V7: 544 | W7: 9259 | X7: =IF(W7=0,MEDIAN($W$2:$W$941),W7) -> 9259 | Y7: 2314 | Z7: {=_xlfn.IFS(OR(R7>66, S7>38), "High Engagement", OR(AND(R7>32, R7<=66), AND(S7>19, S7<=38)), "Medium-High Engagement", OR(AND(R7>4, R7<=32), AND(S7>6, S7<=19)),"Medium Engagement", TRUE, "Low Engagement" )} -> Medium Engagement | AA7: =IF(W7>0, Y7/W7, 0) -> 0.249919
A8: 2320127002 | B8: Mary Davis | C8: =VLOOKUP(user_activity!A152,users_details!$A$1:$G$34,5,0) -> 23 | D8: {=_xlfn.IFS( AND(C8>=18, C8<=25), "Emerging Adults", AND(C8>=26, C8<=35), "Young Adults", AND(C8>=36, C8<=45), "Midlife Adults", AND(C8>=46, C8<=55), "Mature Adults", C8>=56, "Older Adults", TRUE, "Age Not Mentioned")} -> Emerging Adults | E8: =VLOOKUP(user_activity!A152,users_details!$A$1:$G$34,6,0) -> Washington Heights, Manhattan | F8: =VLOOKUP(user_activity!A152,users_details!$A$1:$G$34,7,0) -> Washington Heights | G8: Manhattan | H8: 42487 | I8: =TEXT(H8, "dddd") -> Wednesday | J8: =TEXT(H8, "mmmm") -> April | K8: 1.16 | L8: 1.16 | M8: 0 | N8: 0 | O8: 0 | P8: 1.16 | Q8: 0 | R8: 0 | S8: 0 | T8: 82 | U8: =R8+S8+T8 -> 82 | V8: 1358 | W8: 1715 | X8: =IF(W8=0,MEDIAN($W$2:$W$941),W8) -> 1715 | Y8: 1481 | Z8: {=_xlfn.IFS(OR(R8>66, S8>38), "High Engagement", OR(AND(R8>32, R8<=66), AND(S8>19, S8<=38)), "Medium-High Engagement", OR(AND(R8>4, R8<=32), AND(S8>6, S8<=19)),"Medium Engagement", TRUE, "Low Engagement" )} -> Low Engagement | AA8: =IF(W8>0, Y8/W8, 0) -> 0.86355685
A9: 4319703577 | B9: James Smith | C9: =VLOOKUP(user_activity!A166,users_details!$A$1:$G$34,5,0) -> 23 | D9: {=_xlfn.IFS( AND(C9>=18, C9<=25), "Emerging Adults", AND(C9>=26, C9<=35), "Young Adults", AND(C9>=36, C9<=45), "Midlife Adults", AND(C9>=46, C9<=55), "Mature Adults", C9>=56, "Older Adults", TRUE, "Age Not Mentioned")} -> Emerging Adults | E9: =VLOOKUP(user_activity!A166,users_details!$A$1:$G$34,6,0) -> Crown Heights, Brooklyn | F9: =VLOOKUP(user_activity!A166,users_details!$A$1:$G$34,7,0) -> Crown Heights | G9: Manhattan | H9: 42489 | I9: =TEXT(H9, "dddd") -> Friday | J9: =TEXT(H9, "mmmm") -> April | K9: 5.3600001 | L9: 5.3600001 | M9: 0 | N9: 0.44999999 | O9: 0.79000002 | P9: 4.1199999 | Q9: 0 | R9: 6 | S9: 18 | T9: 289 | U9: =R9+S9+T9 -> 313 | V9: 624 | W9: 7990 | X9: =IF(W9=0,MEDIAN($W$2:$W$941),W9) -> 7990 | Y9: 2175 | Z9: {=_xlfn.IFS(OR(R9>66, S9>38), "High Engagement", OR(AND(R9>32, R9<=66), AND(S9>19, S9<=38)), "Medium-High Engagement", OR(AND(R9>4, R9<=32), AND(S9>6, S9<=19)),"Medium Engagement", TRUE, "Low Engagement" )} -> Medium Engagement | AA9: =IF(W9>0, Y9/W9, 0) -> 0.27221527
A10: 2320127002 | B10: Mary Davis | C10: =VLOOKUP(user_activity!A172,users_details!$A$1:$G$34,5,0) -> 23 | D10: {=_xlfn.IFS( AND(C10>=18, C10<=25), "Emerging Adults", AND(C10>=26, C10<=35), "Young Adults", AND(C10>=36, C10<=45), "Midlife Adults", AND(C10>=46, C10<=55), "Mature Adults", C10>=56, "Older Adults", TRUE, "Age Not Mentioned")} -> Emerging Adults | E10: =VLOOKUP(user_activity!A172,users_details!$A$1:$G$34,6,0) -> Washington Heights, Manhattan | F10: =VLOOKUP(user_activity!A172,users_details!$A$1:$G$34,7,0) -> Washington Heights | G10: Manhattan | H10: 42474 | I10: =TEXT(H10, "dddd") -> Thursday | J10: =TEXT(H10, "mmmm") -> April | K10: 2.6800001 | L10: 2.6800001 | M10: 0 | N10: 0 | O10: 0 | P10: 2.6800001 | Q10: 0 | R10: 0 | S10: 0 | T10: 191 | U10: =R10+S10+T10 -> 191 | V10: 1249 | W10: 3973 | X10: =IF(W10=0,MEDIAN($W$2:$W$941),W10) -> 3973 | Y10: 1696 | Z10: {=_xlfn.IFS(OR(R10>66, S10>38), "High Engagement", OR(AND(R10>32, R10<=66), AND(S10>19, S10<=38)), "Medium-High Engagement", OR(AND(R10>4, R10<=32), AND(S10>6, S10<=19)),"Medium Engagement", TRUE, "Low Engagement" )} -> Low Engagement | AA10: =IF(W10>0, Y10/W10, 0) -> 0.42688145
A11: 4319703577 | B11: James Smith | C11: =VLOOKUP(user_activity!A235,users_details!$A$1:$G$34,5,0) -> 24 | D11: {=_xlfn.IFS( AND(C11>=18, C11<=25), "Emerging Adults", AND(C11>=26, C11<=35), "Young Adults", AND(C11>=36, C11<=45), "Midlife Adults", AND(C11>=46, C11<=55), "Mature Adults", C11>=56, "Older Adults", TRUE, "Age Not Mentioned")} -> Emerging Adults | E11: =VLOOKUP(user_activity!A235,users_details!$A$1:$G$34,6,0) -> East Village, Manhattan | F11: =VLOOKUP(user_activity!A235,users_details!$A$1:$G$34,7,0) -> East Village | G11: Manhattan | H11: 42618 | I11: =TEXT(H11, "dddd") -> Monday | J11: =TEXT(H11, "mmmm") -> September | K11: 6.96 | L11: 6.96 | M11: 0 | N11: 0.14 | O11: 0.56 | P11: 6.25 | Q11: 0 | R11: 2 | S11: 14 | T11: 374 | U11: =R11+S11+T11 -> 390 | V11: 490 | W11: 10378 | X11: =IF(W11=0,MEDIAN($W$2:$W$941),W11) -> 10378 | Y11: 2345 | Z11: {=_xlfn.IFS(OR(R11>66, S11>38), "High Engagement", OR(AND(R11>32, R11<=66), AND(S11>19, S11<=38)), "Medium-High Engagement", OR(AND(R11>4, R11<=32), AND(S11>6, S11<=19)),"Medium Engagement", TRUE, "Low Engagement" )} -> Medium Engagement | AA11: =IF(W11>0, Y11/W11, 0) -> 0.22595876
A12: 4319703577 | B12: James Smith | C12: =VLOOKUP(user_activity!A247,users_details!$A$1:$G$34,5,0) -> 29 | D12: {=_xlfn.IFS( AND(C12>=18, C12<=25), "Emerging Adults", AND(C12>=26, C12<=35), "Young Adults", AND(C12>=36, C12<=45), "Midlife Adults", AND(C12>=46, C12<=55), "Mature Adults", C12>=56, "Older Adults", TRUE, "Age Not Mentioned")} -> Young Adults | E12: =VLOOKUP(user_activity!A247,users_details!$A$1:$G$34,6,0) -> East Village, Manhattan | F12: =VLOOKUP(user_activity!A247,users_details!$A$1:$G$34,7,0) -> East Village | G12: Manhattan | H12: 42479 | I12: =TEXT(H12, "dddd") -> Tuesday | J12: =TEXT(H12, "mmmm") -> April | K12: 5.9899998 | L12: 5.9899998 | M12: 0 | N12: 0 | O12: 0 | P12: 5.9899998 | Q12: 0 | R12: 0 | S12: 0 | T12: 311 | U12: =R12+S12+T12 -> 311 | V12: 604 | W12: 8925 | X12: =IF(W12=0,MEDIAN($W$2:$W$941),W12) -> 8925 | Y12: 2200 | Z12: {=_xlfn.IFS(OR(R12>66, S12>38), "High Engagement", OR(AND(R12>32, R12<=66), AND(S12>19, S12<=38)), "Medium-High Engagement", OR(AND(R12>4, R12<=32), AND(S12>6, S12<=19)),"Medium Engagement", TRUE, "Low Engagement" )} -> Low Engagement | AA12: =IF(W12>0, Y12/W12, 0) -> 0.2464986
A13: 2320127002 | B13: Mary Davis | C13: =VLOOKUP(user_activity!A248,users_details!$A$1:$G$34,5,0) -> 29 | D13: {=_xlfn.IFS( AND(C13>=18, C13<=25), "Emerging Adults", AND(C13>=26, C13<=35), "Young Adults", AND(C13>=36, C13<=45), "Midlife Adults", AND(C13>=46, C13<=55), "Mature Adults", C13>=56, "Older Adults", TRUE, "Age Not Mentioned")} -> Young Adults | E13: =VLOOKUP(user_activity!A248,users_details!$A$1:$G$34,6,0) -> Crown Heights, Brooklyn | F13: =VLOOKUP(user_activity!A248,users_details!$A$1:$G$34,7,0) -> Crown Heights | G13: Manhattan | H13: 42483 | I13: =TEXT(H13, "dddd") -> Saturday | J13: =TEXT(H13, "mmmm") -> April | K13: 3.4200001 | L13: 3.4200001 | M13: 0 | N13: 0 | O13: 0 | P13: 3.4200001 | Q13: 0 | R13: 0 | S13: 0 | T13: 242 | U13: =R13+S13+T13 -> 242 | V13: 1129 | W13: 5079 | X13: =IF(W13=0,MEDIAN($W$2:$W$941),W13) -> 5079 | Y13: 1804 | Z13: {=_xlfn.IFS(OR(R13>66, S13>38), "High Engagement", OR(AND(R13>32, R13<=66), AND(S13>19, S13<=38)), "Medium-High Engagement", OR(AND(R13>4, R13<=32), AND(S13>6, S13<=19)),"Medium Engagement", TRUE, "Low Engagement" )} -> Low Engagement | AA13: =IF(W13>0, Y13/W13, 0) -> 0.35518803
A14: 2320127002 | B14: Mary Davis | C14: =VLOOKUP(user_activity!A276,users_details!$A$1:$G$34,5,0) -> 29 | D14: {=_xlfn.IFS( AND(C14>=18, C14<=25), "Emerging Adults", AND(C14>=26, C14<=35), "Young Adults", AND(C14>=36, C14<=45), "Midlife Adults", AND(C14>=46, C14<=55), "Mature Adults", C14>=56, "Older Adults", TRUE, "Age Not Mentioned")} -> Young Adults | E14: =VLOOKUP(user_activity!A276,users_details!$A$1:$G$34,6,0) -> Crown Heights, Brooklyn | F14: =VLOOKUP(user_activity!A276,users_details!$A$1:$G$34,7,0) -> Crown Heights | G14: Manhattan | H14: 42484 | I14: =TEXT(H14, "dddd") -> Sunday | J14: =TEXT(H14, "mmmm") -> April | K14: 2.8099999 | L14: 2.8099999 | M14: 0 | N14: 0 | O14: 0 | P14: 2.8 | Q14: 0 | R14: 0 | S14: 0 | T14: 204 | U14: =R14+S14+T14 -> 204 | V14: 1236 | W14: 4165 | X14: =IF(W14=0,MEDIAN($W$2:$W$941),W14) -> 4165 | Y14: 1725 | Z14: {=_xlfn.IFS(OR(R14>66, S14>38), "High Engagement", OR(AND(R14>32, R14<=66), AND(S14>19, S14<=38)), "Medium-High Engagement", OR(AND(R14>4, R14<=32), AND(S14>6, S14<=19)),"Medium Engagement", TRUE, "Low Engagement" )} -> Low Engagement | AA14: =IF(W14>0, Y14/W14, 0) -> 0.41416567
A15: 4319703577 | B15: James Smith | C15: =VLOOKUP(user_activity!A296,users_details!$A$1:$G$34,5,0) -> 29 | D15: {=_xlfn.IFS( AND(C15>=18, C15<=25), "Emerging Adults", AND(C15>=26, C15<=35), "Young Adults", AND(C15>=36, C15<=45), "Midlife Adults", AND(C15>=46, C15<=55), "Mature Adults", C15>=56, "Older Adults", TRUE, "Age Not Mentioned")} -> Young Adults | E15: =VLOOKUP(user_activity!A296,users_details!$A$1:$G$34,6,0) -> East Village, Manhattan | F15: =VLOOKUP(user_activity!A296,users_details!$A$1:$G$34,7,0) -> East Village | G15: Manhattan | H15: 42648 | I15: =TEXT(H15, "dddd") -> Wednesday | J15: =TEXT(H15, "mmmm") -> October | K15: 6.3699999 | L15: 6.3699999 | M15: 0 | N15: 0.20999999 | O15: 0.46000001 | P15: 5.6999998 | Q15: 0 | R15: 3 | S15: 12 | T15: 329 | U15: =R15+S15+T15 -> 344 | V15: 555 | W15: 9487 | X15: =IF(W15=0,MEDIAN($W$2:$W$941),W15) -> 9487 | Y15: 2260 | Z15: {=_xlfn.IFS(OR(R15>66, S15>38), "High Engagement", OR(AND(R15>32, R15<=66), AND(S15>19, S15<=38)), "Medium-High Engagement", OR(AND(R15>4, R15<=32), AND(S15>6, S15<=19)),"Medium Engagement", TRUE, "Low Engagement" )} -> Medium Engagement | AA15: =IF(W15>0, Y15/W15, 0) -> 0.23822072
A16: 2320127002 | B16: Mary Davis | C16: =VLOOKUP(user_activity!A334,users_details!$A$1:$G$34,5,0) -> 30 | D16: {=_xlfn.IFS( AND(C16>=18, C16<=25), "Emerging Adults", AND(C16>=26, C16<=35), "Young Adults", AND(C16>=36, C16<=45), "Midlife Adults", AND(C16>=46, C16<=55), "Mature Adults", C16>=56, "Older Adults", TRUE, "Age Not Mentioned")} -> Young Adults | E16: =VLOOKUP(user_activity!A334,users_details!$A$1:$G$34,6,0) -> Midtown, Manhattan | F16: =VLOOKUP(user_activity!A334,users_details!$A$1:$G$34,7,0) -> Midtown | G16: Manhattan | H16: 42490 | I16: =TEXT(H16, "dddd") -> Saturday | J16: =TEXT(H16, "mmmm") -> April | K16: 3.0799999 | L16: 3.0799999 | M16: 0 | N16: 0 | O16: 0 | P16: 3.0699999 | Q16: 0 | R16: 0 | S16: 0 | T16: 234 | U16: =R16+S16+T16 -> 234 | V16: 1206 | W16: 4571 | X16: =IF(W16=0,MEDIAN($W$2:$W$941),W16) -> 4571 | Y16: 1779 | Z16: {=_xlfn.IFS(OR(R16>66, S16>38), "High Engagement", OR(AND(R16>32, R16<=66), AND(S16>19, S16<=38)), "Medium-High Engagement", OR(AND(R16>4, R16<=32), AND(S16>6, S16<=19)),"Medium Engagement", TRUE, "Low Engagement" )} -> Low Engagement | AA16: =IF(W16>0, Y16/W16, 0) -> 0.38919274
A17: 2320127002 | B17: Mary Davis | C17: =VLOOKUP(user_activity!A335,users_details!$A$1:$G$34,5,0) -> 30 | D17: {=_xlfn.IFS( AND(C17>=18, C17<=25), "Emerging Adults", AND(C17>=26, C17<=35), "Young Adults", AND(C17>=36, C17<=45), "Midlife Adults", AND(C17>=46, C17<=55), "Mature Adults", C17>=56, "Older Adults", TRUE, "Age Not Mentioned")} -> Young Adults | E17: =VLOOKUP(user_activity!A335,users_details!$A$1:$G$34,6,0) -> Midtown, Manhattan | F17: =VLOOKUP(user_activity!A335,users_details!$A$1:$G$34,7,0) -> Midtown | G17: Manhattan | H17: 42476 | I17: =TEXT(H17, "dddd") -> Saturday | J17: =TEXT(H17, "mmmm") -> April | K17: 3.4100001 | L17: 3.4100001 | M17: 0 | N17: 0 | O17: 0 | P17: 3.4000001 | Q17: 0 | R17: 0 | S17: 0 | T17: 195 | U17: =R17+S17+T17 -> 195 | V17: 1245 | W17: 5057 | X17: =IF(W17=0,MEDIAN($W$2:$W$941),W17) -> 5057 | Y17: 1724 | Z17: {=_xlfn.IFS(OR(R17>66, S17>38), "High Engagement", OR(AND(R17>32, R17<=66), AND(S17>19, S17<=38)), "Medium-High Engagement", OR(AND(R17>4, R17<=32), AND(S17>6, S17<=19)),"Medium Engagement", TRUE, "Low Engagement" )} -> Low Engagement | AA17: =IF(W17>0, Y17/W17, 0) -> 0.34091359
A18: 4319703577 | B18: James Smith | C18: =VLOOKUP(user_activity!A348,users_details!$A$1:$G$34,5,0) -> 31 | D18: {=_xlfn.IFS( AND(C18>=18, C18<=25), "Emerging Adults", AND(C18>=26, C18<=35), "Young Adults", AND(C18>=36, C18<=45), "Midlife Adults", AND(C18>=46, C18<=55), "Mature Adults", C18>=56, "Older Adults", TRUE, "Age Not Mentioned")} -> Young Adults | E18: =VLOOKUP(user_activity!A348,users_details!$A$1:$G$34,6,0) -> Midtown, Manhattan | F18: =VLOOKUP(user_activity!A348,users_details!$A$1:$G$34,7,0) -> Midtown | G18: Manhattan | H18: 42708 | I18: =TEXT(H18, "dddd") -> Sunday | J18: =TEXT(H18, "mmmm") -> December | K18: 5.1999998 | L18: 5.1999998 | M18: 0 | N18: 0 | O18: 0 | P18: 0 | Q18: 0 | R18: 0 | S18: 0 | T18: 0 | U18: =R18+S18+T18 -> 0 | V18: 1440 | W18: 7753 | X18: =IF(W18=0,MEDIAN($W$2:$W$941),W18) -> 7753 | Y18: 2115 | Z18: {=_xlfn.IFS(OR(R18>66, S18>38), "High Engagement", OR(AND(R18>32, R18<=66), AND(S18>19, S18<=38)), "Medium-High Engagement", OR(AND(R18>4, R18<=32), AND(S18>6, S18<=19)),"Medium Engagement", TRUE, "Low Engagement" )} -> Low Engagement | AA18: =IF(W18>0, Y18/W18, 0) -> 0.27279763
A19: 4319703577 | B19: James Smith | C19: =VLOOKUP(user_activity!A351,users_details!$A$1:$G$34,5,0) -> 31 | D19: {=_xlfn.IFS( AND(C19>=18, C19<=25), "Emerging Adults", AND(C19>=26, C19<=35), "Young Adults", AND(C19>=36, C19<=45), "Midlife Adults", AND(C19>=46, C19<=55), "Mature Adults", C19>=56, "Older Adults", TRUE, "Age Not Mentioned")} -> Young Adults | E19: =VLOOKUP(user_activity!A351,users_details!$A$1:$G$34,6,0) -> Midtown, Manhattan | F19: =VLOOKUP(user_activity!A351,users_details!$A$1:$G$34,7,0) -> Midtown | G19: Manhattan | H19: 42709 | I19: =TEXT(H19, "dddd") -> Monday | J19: =TEXT(H19, "mmmm") -> December | K19: 0.01 | L19: 0.01 | M19: 0 | N19: 0 | O19: 0 | P19: 0.01 | Q19: 0 | R19: 0 | S19: 0 | T19: 2 | U19: =R19+S19+T19 -> 2 | V19: 0 | W19: 17 | X19: =IF(W19=0,MEDIAN($W$2:$W$941),W19) -> 17 | Y19: 257 | Z19: {=_xlfn.IFS(OR(R19>66, S19>38), "High Engagement", OR(AND(R19>32, R19<=66), AND(S19>19, S19<=38)), "Medium-High Engagement", OR(AND(R19>4, R19<=32), AND(S19>6, S19<=19)),"Medium Engagement", TRUE, "Low Engagement" )} -> Low Engagement | AA19: 0
A20: 2320127002 | B20: Mary Davis | C20: =VLOOKUP(user_activity!A381,users_details!$A$1:$G$34,5,0) -> 32 | D20: {=_xlfn.IFS( AND(C20>=18, C20<=25), "Emerging Adults", AND(C20>=26, C20<=35), "Young Adults", AND(C20>=36, C20<=45), "Midlife Adults", AND(C20>=46, C20<=55), "Mature Adults", C20>=56, "Older Adults", TRUE, "Age Not Mentioned")} -> Young Adults | E20: =VLOOKUP(user_activity!A381,users_details!$A$1:$G$34,6,0) -> Greenpoint, Brooklyn | F20: =VLOOKUP(user_activity!A381,users_details!$A$1:$G$34,7,0) -> Greenpoint | G20: Manhattan | H20: 42479 | I20: =TEXT(H20, "dddd") -> Tuesday | J20: =TEXT(H20, "mmmm") -> April | K20: 4.04 | L20: 4.04 | M20: 0 | N20: 0 | O20: 0.37999999 | P20: 3.6600001 | Q20: 0 | R20: 0 | S20: 11 | T20: 228 | U20: =R20+S20+T20 -> 239 | V20: 1201 | W20: 5997 | X20: =IF(W20=0,MEDIAN($W$2:$W$941),W20) -> 5997 | Y20: 1811 | Z20: {=_xlfn.IFS(OR(R20>66, S20>38), "High Engagement", OR(AND(R20>32, R20<=66), AND(S20>19, S20<=38)), "Medium-High Engagement", OR(AND(R20>4, R20<=32), AND(S20>6, S20<=19)),"Medium Engagement", TRUE, "Low Engagement" )} -> Medium Engagement | AA20: =IF(W20>0, Y20/W20, 0) -> 0.30198433
A21: 4319703577 | B21: James Smith | C21: =VLOOKUP(user_activity!A401,users_details!$A$1:$G$34,5,0) -> 32 | D21: {=_xlfn.IFS( AND(C21>=18, C21<=25), "Emerging Adults", AND(C21>=26, C21<=35), "Young Adults", AND(C21>=36, C21<=45), "Midlife Adults", AND(C21>=46, C21<=55), "Mature Adults", C21>=56, "Older Adults", TRUE, "Age Not Mentioned")} -> Young Adults | E21: =VLOOKUP(user_activity!A401,users_details!$A$1:$G$34,6,0) -> East Harlem, Manhattan | F21: =VLOOKUP(user_activity!A401,users_details!$A$1:$G$34,7,0) -> East Harlem | G21: Manhattan | H21: 42481 | I21: =TEXT(H21, "dddd") -> Thursday | J21: =TEXT(H21, "mmmm") -> April | K21: 2.48 | L21: 2.48 | M21: 0 | N21: 0 | O21: 0 | P21: 0.34999999 | Q21: 0 | R21: 0 | S21: 0 | T21: 34 | U21: =R21+S21+T21 -> 34 | V21: 1265 | W21: 3702 | X21: =IF(W21=0,MEDIAN($W$2:$W$941),W21) -> 3702 | Y21: 1792 | Z21: {=_xlfn.IFS(OR(R21>66, S21>38), "High Engagement", OR(AND(R21>32, R21<=66), AND(S21>19, S21<=38)), "Medium-High Engagement", OR(AND(R21>4, R21<=32), AND(S21>6, S21<=19)),"Medium Engagement", TRUE, "Low Engagement" )} -> Low Engagement | AA21: =IF(W21>0, Y21/W21, 0) -> 0.48406267
A22: 4319703577 | B22: James Smith | C22: =VLOOKUP(user_activity!A404,users_details!$A$1:$G$34,5,0) -> 32 | D22: {=_xlfn.IFS( AND(C22>=18, C22<=25), "Emerging Adults", AND(C22>=26, C22<=35), "Young Adults", AND(C22>=36, C22<=45), "Midlife Adults", AND(C22>=46, C22<=55), "Mature Adults", C22>=56, "Older Adults", TRUE, "Age Not Mentioned")} -> Young Adults | E22: =VLOOKUP(user_activity!A404,users_details!$A$1:$G$34,6,0) -> Greenpoint, Brooklyn | F22: =VLOOKUP(user_activity!A404,users_details!$A$1:$G$34,7,0) -> Greenpoint | G22: Manhattan | H22: 42526 | I22: =TEXT(H22, "dddd") -> Sunday | J22: =TEXT(H22, "mmmm") -> June | K22: 6.4200001 | L22: 6.4200001 | M22: 0 | N22: 0.41 | O22: 0.47 | P22: 5.46 | Q22: 0 | R22: 6 | S22: 11 | T22: 314 | U22: =R22+S22+T22 -> 331 | V22: 692 | W22: 9524 | X22: =IF(W22=0,MEDIAN($W$2:$W$941),W22) -> 9524 | Y22: 2266 | Z22: {=_xlfn.IFS(OR(R22>66, S22>38), "High Engagement", OR(AND(R22>32, R22<=66), AND(S22>19, S22<=38)), "Medium-High Engagement", OR(AND(R22>4, R22<=32), AND(S22>6, S22<=19)),"Medium Engagement", TRUE, "Low Engagement" )} -> Medium Engagement | AA22: =IF(W22>0, Y22/W22, 0) -> 0.23792524
A23: 4319703577 | B23: James Smith | C23: =VLOOKUP(user_activity!A417,users_details!$A$1:$G$34,5,0) -> 32 | D23: {=_xlfn.IFS( AND(C23>=18, C23<=25), "Emerging Adults", AND(C23>=26, C23<=35), "Young Adults", AND(C23>=36, C23<=45), "Midlife Adults", AND(C23>=46, C23<=55), "Mature Adults", C23>=56, "Older Adults", TRUE, "Age Not Mentioned")} -> Young Adults | E23: =VLOOKUP(user_activity!A417,users_details!$A$1:$G$34,6,0) -> East Harlem, Manhattan | F23: =VLOOKUP(user_activity!A417,users_details!$A$1:$G$34,7,0) -> East Harlem | G23: Manhattan | H23: 42487 | I23: =TEXT(H23, "dddd") -> Wednesday | J23: =TEXT(H23, "mmmm") -> April | K23: 7.23 | L23: 7.23 | M23: 0 | N23: 0.41 | O23: 1.92 | P23: 4.9099998 | Q23: 0 | R23: 6 | S23: 47 | T23: 300 | U23: =R23+S23+T23 -> 353 | V23: 680 | W23: 10780 | X23: =IF(W23=0,MEDIAN($W$2:$W$941),W23) -> 10780 | Y23: 2324 | Z23: {=_xlfn.IFS(OR(R23>66, S23>38), "High Engagement", OR(AND(R23>32, R23<=66), AND(S23>19, S23<=38)), "Medium-High Engagement", OR(AND(R23>4, R23<=32), AND(S23>6, S23<=19)),"Medium Engagement", TRUE, "Low Engagement" )} -> High Engagement | AA23: =IF(W23>0, Y23/W23, 0) -> 0.21558442
A24: 4319703577 | B24: James Smith | C24: =VLOOKUP(user_activity!A438,users_details!$A$1:$G$34,5,0) -> 32 | D24: {=_xlfn.IFS( AND(C24>=18, C24<=25), "Emerging Adults", AND(C24>=26, C24<=35), "Young Adults", AND(C24>=36, C24<=45), "Midlife Adults", AND(C24>=46, C24<=55), "Mature Adults", C24>=56, "Older Adults", TRUE, "Age Not Mentioned")} -> Young Adults | E24: =VLOOKUP(user_activity!A438,users_details!$A$1:$G$34,6,0) -> Greenpoint, Brooklyn | F24: =VLOOKUP(user_activity!A438,users_details!$A$1:$G$34,7,0) -> Greenpoint | G24: Manhattan | H24: 42474 | I24: =TEXT(H24, "dddd") -> Thursday | J24: =TEXT(H24, "mmmm") -> April | K24: 6.8800001 | L24: 6.8800001 | M24: 0 | N24: 0.11 | O24: 0.33000001 | P24: 6.4400001 | Q24: 0 | R24: 1 | S24: 9 | T24: 339 | U24: =R24+S24+T24 -> 349 | V24: 589 | W24: 10210 | X24: =IF(W24=0,MEDIAN($W$2:$W$941),W24) -> 10210 | Y24: 2302 | Z24: {=_xlfn.IFS(OR(R24>66, S24>38), "High Engagement", OR(AND(R24>32, R24<=66), AND(S24>19, S24<=38)), "Medium-High Engagement", OR(AND(R24>4, R24<=32), AND(S24>6, S24<=19)),"Medium Engagement", TRUE, "Low Engagement" )} -> Medium Engagement | AA24: =IF(W24>0, Y24/W24, 0) -> 0.22546523
A25: 4319703577 | B25: James Smith | C25: =VLOOKUP(user_activity!A451,users_details!$A$1:$G$34,5,0) -> 33 | D25: {=_xlfn.IFS( AND(C25>=18, C25<=25), "Emerging Adults", AND(C25>=26, C25<=35), "Young Adults", AND(C25>=36, C25<=45), "Midlife Adults", AND(C25>=46, C25<=55), "Mature Adults", C25>=56, "Older Adults", TRUE, "Age Not Mentioned")} -> Young Adults | E25: =VLOOKUP(user_activity!A451,users_details!$A$1:$G$34,6,0) -> Harlem, Manhattan | F25: =VLOOKUP(user_activity!A451,users_details!$A$1:$G$34,7,0) -> Harlem | G25: Manhattan | H25: 42484 | I25: =TEXT(H25, "dddd") -> Sunday | J25: =TEXT(H25, "mmmm") -> April | K25: 2.74 | L25: 2.74 | M25: 0 | N25: 0.059999999 | O25: 0.2 | P25: 2.47 | Q25: 0 | R25: 1 | S25: 5 | T25: 191 | U25: =R25+S25+T25 -> 197 | V25: 692 | W25: 4081 | X25: =IF(W25=0,MEDIAN($W$2:$W$941),W25) -> 4081 | Y25: 1880 | Z25: {=_xlfn.IFS(OR(R25>66, S25>38), "High Engagement", OR(AND(R25>32, R25<=66), AND(S25>19, S25<=38)), "Medium-High Engagement", OR(AND(R25>4, R25<=32), AND(S25>6, S25<=19)),"Medium Engagement", TRUE, "Low Engagement" )} -> Low Engagement | AA25: =IF(W25>0, Y25/W25, 0) -> 0.4606714
A26: 2320127002 | B26: Mary Davis | C26: =VLOOKUP(user_activity!A452,users_details!$A$1:$G$34,5,0) -> 33 | D26: {=_xlfn.IFS( AND(C26>=18, C26<=25), "Emerging Adults", AND(C26>=26, C26<=35), "Young Adults", AND(C26>=36, C26<=45), "Midlife Adults", AND(C26>=46, C26<=55), "Mature Adults", C26>=56, "Older Adults", TRUE, "Age Not Mentioned")} -> Young Adults | E26: =VLOOKUP(user_activity!A452,users_details!$A$1:$G$34,6,0) -> Harlem, Manhattan | F26: =VLOOKUP(user_activity!A452,users_details!$A$1:$G$34,7,0) -> Harlem | G26: Manhattan | H26: 42478 | I26: =TEXT(H26, "dddd") -> Monday | J26: =TEXT(H26, "mmmm") -> April | K26: 4.4200001 | L26: 4.4200001 | M26: 0 | N26: 0 | O26: 0.25999999 | P26: 4.1399999 | Q26: 0 | R26: 0 | S26: 7 | T26: 260 | U26: =R26+S26+T26 -> 267 | V26: 1173 | W26: 6559 | X26: =IF(W26=0,MEDIAN($W$2:$W$941),W26) -> 6559 | Y26: 1905 | Z26: {=_xlfn.IFS(OR(R26>66, S26>38), "High Engagement", OR(AND(R26>32, R26<=66), AND(S26>19, S26<=38)), "Medium-High Engagement", OR(AND(R26>4, R26<=32), AND(S26>6, S26<=19)),"Medium Engagement", TRUE, "Low Engagement" )} -> Medium Engagement | AA26: =IF(W26>0, Y26/W26, 0) -> 0.29044062
A27: 2320127002 | B27: Mary Davis | C27: =VLOOKUP(user_activity!A462,users_details!$A$1:$G$34,5,0) -> 33 | D27: {=_xlfn.IFS( AND(C27>=18, C27<=25), "Emerging Adults", AND(C27>=26, C27<=35), "Young Adults", AND(C27>=36, C27<=45), "Midlife Adults", AND(C27>=46, C27<=55), "Mature Adults", C27>=56, "Older Adults", TRUE, "Age Not Mentioned")} -> Young Adults | E27: =VLOOKUP(user_activity!A462,users_details!$A$1:$G$34,6,0) -> Harlem, Manhattan | F27: =VLOOKUP(user_activity!A462,users_details!$A$1:$G$34,7,0) -> Harlem | G27: Manhattan | H27: 42477 | I27: =TEXT(H27, "dddd") -> Sunday | J27: =TEXT(H27, "mmmm") -> April | K27: 4.1799998 | L27: 4.1799998 | M27: 0 | N27: 0 | O27: 0 | P27: 4.1799998 | Q27: 0 | R27: 0 | S27: 0 | T27: 249 | U27: =R27+S27+T27 -> 249 | V27: 1191 | W27: 6198 | X27: =IF(W27=0,MEDIAN($W$2:$W$941),W27) -> 6198 | Y27: 1852 | Z27: {=_xlfn.IFS(OR(R27>66, S27>38), "High Engagement", OR(AND(R27>32, R27<=66), AND(S27>19, S27<=38)), "Medium-High Engagement", OR(AND(R27>4, R27<=32), AND(S27>6, S27<=19)),"Medium Engagement", TRUE, "Low Engagement" )} -> Low Engagement | AA27: =IF(W27>0, Y27/W27, 0) -> 0.29880607
A28: 2320127002 | B28: Mary Davis | C28: =VLOOKUP(user_activity!A474,users_details!$A$1:$G$34,5,0) -> 33 | D28: {=_xlfn.IFS( AND(C28>=18, C28<=25), "Emerging Adults", AND(C28>=26, C28<=35), "Young Adults", AND(C28>=36, C28<=45), "Midlife Adults", AND(C28>=46, C28<=55), "Mature Adults", C28>=56, "Older Adults", TRUE, "Age Not Mentioned")} -> Young Adults | E28: =VLOOKUP(user_activity!A474,users_details!$A$1:$G$34,6,0) -> Greenpoint, Brooklyn | F28: =VLOOKUP(user_activity!A474,users_details!$A$1:$G$34,7,0) -> Greenpoint | G28: Manhattan | H28: 42434 | I28: =TEXT(H28, "dddd") -> Saturday | J28: =TEXT(H28, "mmmm") -> March | K28: 5.02 | L28: 5.02 | M28: 0 | N28: 1.49 | O28: 0.37000001 | P28: 3.1600001 | Q28: 0 | R28: 20 | S28: 10 | T28: 206 | U28: =R28+S28+T28 -> 236 | V28: 1204 | W28: 7443 | X28: =IF(W28=0,MEDIAN($W$2:$W$941),W28) -> 7443 | Y28: 1878 | Z28: {=_xlfn.IFS(OR(R28>66, S28>38), "High Engagement", OR(AND(R28>32, R28<=66), AND(S28>19, S28<=38)), "Medium-High Engagement", OR(AND(R28>4, R28<=32), AND(S28>6, S28<=19)),"Medium Engagement", TRUE, "Low Engagement" )} -> Medium Engagement | AA28: =IF(W28>0, Y28/W28, 0) -> 0.25231761
A29: 2320127002 | B29: Mary Davis | C29: =VLOOKUP(user_activity!A499,users_details!$A$1:$G$34,5,0) -> 36 | D29: {=_xlfn.IFS( AND(C29>=18, C29<=25), "Emerging Adults", AND(C29>=26, C29<=35), "Young Adults", AND(C29>=36, C29<=45), "Midlife Adults", AND(C29>=46, C29<=55), "Mature Adults", C29>=56, "Older Adults", TRUE, "Age Not Mentioned")} -> Midlife Adults | E29: =VLOOKUP(user_activity!A499,users_details!$A$1:$G$34,6,0) -> Williamsburg, Brooklyn | F29: =VLOOKUP(user_activity!A499,users_details!$A$1:$G$34,7,0) -> Williamsburg | G29: Manhattan | H29: 42405 | I29: =TEXT(H29, "dddd") -> Friday | J29: =TEXT(H29, "mmmm") -> February | K29: 2.45 | L29: 2.45 | M29: 0 | N29: 0.36000001 | O29: 0.20999999 | P29: 1.88 | Q29: 0 | R29: 5 | S29: 6 | T29: 123 | U29: =R29+S29+T29 -> 134 | V29: 1306 | W29: 3634 | X29: =IF(W29=0,MEDIAN($W$2:$W$941),W29) -> 3634 | Y29: 1613 | Z29: {=_xlfn.IFS(OR(R29>66, S29>38), "High Engagement", OR(AND(R29>32, R29<=66), AND(S29>19, S29<=38)), "Medium-High Engagement", OR(AND(R29>4, R29<=32), AND(S29>6, S29<=19)),"Medium Engagement", TRUE, "Low Engagement" )} -> Medium Engagement | AA29: =IF(W29>0, Y29/W29, 0) -> 0.44386351
A30: 2320127002 | B30: Mary Davis | C30: =VLOOKUP(user_activity!A507,users_details!$A$1:$G$34,5,0) -> 36 | D30: {=_xlfn.IFS( AND(C30>=18, C30<=25), "Emerging Adults", AND(C30>=26, C30<=35), "Young Adults", AND(C30>=36, C30<=45), "Midlife Adults", AND(C30>=46, C30<=55), "Mature Adults", C30>=56, "Older Adults", TRUE, "Age Not Mentioned")} -> Midlife Adults | E30: =VLOOKUP(user_activity!A507,users_details!$A$1:$G$34,6,0) -> Williamsburg, Brooklyn | F30: =VLOOKUP(user_activity!A507,users_details!$A$1:$G$34,7,0) -> Williamsburg | G30: Manhattan | H30: 42465 | I30: =TEXT(H30, "dddd") -> Tuesday | J30: =TEXT(H30, "mmmm") -> April | K30: 0.81 | L30: 0.81 | M30: 0 | N30: 0 | O30: 0 | P30: 0.81 | Q30: 0 | R30: 0 | S30: 0 | T30: 52 | U30: =R30+S30+T30 -> 52 | V30: 1388 | W30: 1201 | X30: =IF(W30=0,MEDIAN($W$2:$W$941),W30) -> 1201 | Y30: 1426 | Z30: {=_xlfn.IFS(OR(R30>66, S30>38), "High Engagement", OR(AND(R30>32, R30<=66), AND(S30>19, S30<=38)), "Medium-High Engagement", OR(AND(R30>4, R30<=32), AND(S30>6, S30<=19)),"Medium Engagement", TRUE, "Low Engagement" )} -> Low Engagement | AA30: =IF(W30>0, Y30/W30, 0) -> 1.1873439
A31: 4319703577 | B31: James Smith | C31: =VLOOKUP(user_activity!A513,users_details!$A$1:$G$34,5,0) -> 36 | D31: {=_xlfn.IFS( AND(C31>=18, C31<=25), "Emerging Adults", AND(C31>=26, C31<=35), "Young Adults", AND(C31>=36, C31<=45), "Midlife Adults", AND(C31>=46, C31<=55), "Mature Adults", C31>=56, "Older Adults", TRUE, "Age Not Mentioned")} -> Midlife Adults | E31: =VLOOKUP(user_activity!A513,users_details!$A$1:$G$34,6,0) -> Williamsburg, Brooklyn | F31: =VLOOKUP(user_activity!A513,users_details!$A$1:$G$34,7,0) -> Williamsburg | G31: Manhattan | H31: 42486 | I31: =TEXT(H31, "dddd") -> Tuesday | J31: =TEXT(H31, "mmmm") -> April | K31: 6.6399999 | L31: 6.6399999 | M31: 0 | N31: 0.56999999 | O31: 0.92000002 | P31: 5.1500001 | Q31: 0 | R31: 8 | S31: 21 | T31: 288 | U31: =R31+S31+T31 -> 317 | V31: 649 | W31: 9899 | X31: =IF(W31=0,MEDIAN($W$2:$W$941),W31) -> 9899 | Y31: 2236 | Z31: {=_xlfn.IFS(OR(R31>66, S31>38), "High Engagement", OR(AND(R31>32, R31<=66), AND(S31>19, S31<=38)), "Medium-High Engagement", OR(AND(R31>4, R31<=32), AND(S31>6, S31<=19)),"Medium Engagement", TRUE, "Low Engagement" )} -> Medium-High Engagement | AA31: =IF(W31>0, Y31/W31, 0) -> 0.2258814
A32: 4319703577 | B32: James Smith | C32: =VLOOKUP(user_activity!A544,users_details!$A$1:$G$34,5,0) -> 38 | D32: {=_xlfn.IFS( AND(C32>=18, C32<=25), "Emerging Adults", AND(C32>=26, C32<=35), "Young Adults", AND(C32>=36, C32<=45), "Midlife Adults", AND(C32>=46, C32<=55), "Mature Adults", C32>=56, "Older Adults", TRUE, "Age Not Mentioned")} -> Midlife Adults | E32: =VLOOKUP(user_activity!A544,users_details!$A$1:$G$34,6,0) -> Midtown, Manhattan | F32: =VLOOKUP(user_activity!A544,users_details!$A$1:$G$34,7,0) -> Midtown | G32: Manhattan | H32: 42490 | I32: =TEXT(H32, "dddd") -> Saturday | J32: =TEXT(H32, "mmmm") -> April | K32: 5.52 | L32: 5.52 | M32: 0 | N32: 0.40000001 | O32: 1.61 | P32: 3.51 | Q32: 0 | R32: 6 | S32: 38 | T32: 196 | U32: =R32+S32+T32 -> 240 | V32: 695 | W32: 8221 | X32: =IF(W32=0,MEDIAN($W$2:$W$941),W32) -> 8221 | Y32: 2092 | Z32: {=_xlfn.IFS(OR(R32>66, S32>38), "High Engagement", OR(AND(R32>32, R32<=66), AND(S32>19, S32<=38)), "Medium-High Engagement", OR(AND(R32>4, R32<=32), AND(S32>6, S32<=19)),"Medium Engagement", TRUE, "Low Engagement" )} -> Medium-High Engagement | AA32: =IF(W32>0, Y32/W32, 0) -> 0.25447026
A33: 4319703577 | B33: James Smith | C33: =VLOOKUP(user_activity!A551,users_details!$A$1:$G$34,5,0) -> 38 | D33: {=_xlfn.IFS( AND(C33>=18, C33<=25), "Emerging Adults", AND(C33>=26, C33<=35), "Young Adults", AND(C33>=36, C33<=45), "Midlife Adults", AND(C33>=46, C33<=55), "Mature Adults", C33>=56, "Older Adults", TRUE, "Age Not Mentioned")} -> Midlife Adults | E33: =VLOOKUP(user_activity!A551,users_details!$A$1:$G$34,6,0) -> East Harlem, Manhattan | F33: =VLOOKUP(user_activity!A551,users_details!$A$1:$G$34,7,0) -> East Harlem | G33: Manhattan | H33: 42587 | I33: =TEXT(H33, "dddd") -> Friday | J33: =TEXT(H33, "mmmm") -> August | K33: 2.46 | L33: 2.46 | M33: 0 | N33: 0 | O33: 0 | P33: 2.46 | Q33: 0 | R33: 0 | S33: 0 | T33: 153 | U33: =R33+S33+T33 -> 153 | V33: 603 | W33: 3672 | X33: =IF(W33=0,MEDIAN($W$2:$W$941),W33) -> 3672 | Y33: 1792 | Z33: {=_xlfn.IFS(OR(R33>66, S33>38), "High Engagement", OR(AND(R33>32, R33<=66), AND(S33>19, S33<=38)), "Medium-High Engagement", OR(AND(R33>4, R33<=32), AND(S33>6, S33<=19)),"Medium Engagement", TRUE, "Low Engagement" )} -> Low Engagement | AA33: =IF(W33>0, Y33/W33, 0) -> 0.48801743
A34: 2320127002 | B34: Mary Davis | C34: =VLOOKUP(user_activity!A556,users_details!$A$1:$G$34,5,0) -> 38 | D34: {=_xlfn.IFS( AND(C34>=18, C34<=25), "Emerging Adults", AND(C34>=26, C34<=35), "Young Adults", AND(C34>=36, C34<=45), "Midlife Adults", AND(C34>=46, C34<=55), "Mature Adults", C34>=56, "Older Adults", TRUE, "Age Not Mentioned")} -> Midlife Adults | E34: =VLOOKUP(user_activity!A556,users_details!$A$1:$G$34,6,0) -> Midtown, Manhattan | F34: =VLOOKUP(user_activity!A556,users_details!$A$1:$G$34,7,0) -> Midtown | G34: Manhattan | H34: 42679 | I34: =TEXT(H34, "dddd") -> Saturday | J34: =TEXT(H34, "mmmm") -> November | K34: 4.3299999 | L34: 4.3299999 | M34: 0 | N34: 0 | O34: 0 | P34: 4.3299999 | Q34: 0 | R34: 0 | S34: 0 | T34: 300 | U34: =R34+S34+T34 -> 300 | V34: 1140 | W34: 6424 | X34: =IF(W34=0,MEDIAN($W$2:$W$941),W34) -> 6424 | Y34: 1903 | Z34: {=_xlfn.IFS(OR(R34>66, S34>38), "High Engagement", OR(AND(R34>32, R34<=66), AND(S34>19, S34<=38)), "Medium-High Engagement", OR(AND(R34>4, R34<=32), AND(S34>6, S34<=19)),"Medium Engagement", TRUE, "Low Engagement" )} -> Low Engagement | AA34: =IF(W34>0, Y34/W34, 0) -> 0.29623288
A35: 2320127002 | B35: Mary Davis | C35: =VLOOKUP(user_activity!A597,users_details!$A$1:$G$34,5,0) -> 39 | D35: {=_xlfn.IFS( AND(C35>=18, C35<=25), "Emerging Adults", AND(C35>=26, C35<=35), "Young Adults", AND(C35>=36, C35<=45), "Midlife Adults", AND(C35>=46, C35<=55), "Mature Adults", C35>=56, "Older Adults", TRUE, "Age Not Mentioned")} -> Midlife Adults | E35: =VLOOKUP(user_activity!A597,users_details!$A$1:$G$34,6,0) -> East Village, Manhattan | F35: =VLOOKUP(user_activity!A597,users_details!$A$1:$G$34,7,0) -> East Village | G35: Manhattan | H35: 42481 | I35: =TEXT(H35, "dddd") -> Thursday | J35: =TEXT(H35, "mmmm") -> April | K35: 2.29 | L35: 2.29 | M35: 0 | N35: 0.059999999 | O35: 0.41999999 | P35: 1.8099999 | Q35: 0 | R35: 1 | S35: 10 | T35: 127 | U35: =R35+S35+T35 -> 138 | V35: 1302 | W35: 3404 | X35: =IF(W35=0,MEDIAN($W$2:$W$941),W35) -> 3404 | Y35: 1610 | Z35: {=_xlfn.IFS(OR(R35>66, S35>38), "High Engagement", OR(AND(R35>32, R35<=66), AND(S35>19, S35<=38)), "Medium-High Engagement", OR(AND(R35>4, R35<=32), AND(S35>6, S35<=19)),"Medium Engagement", TRUE, "Low Engagement" )} -> Medium Engagement | AA35: =IF(W35>0, Y35/W35, 0) -> 0.47297297
A36: 2320127002 | B36: Mary Davis | C36: =VLOOKUP(user_activity!A603,users_details!$A$1:$G$34,5,0) -> 39 | D36: {=_xlfn.IFS( AND(C36>=18, C36<=25), "Emerging Adults", AND(C36>=26, C36<=35), "Young Adults", AND(C36>=36, C36<=45), "Midlife Adults", AND(C36>=46, C36<=55), "Mature Adults", C36>=56, "Older Adults", TRUE, "Age Not Mentioned")} -> Midlife Adults | E36: =VLOOKUP(user_activity!A603,users_details!$A$1:$G$34,6,0) -> East Village, Manhattan | F36: =VLOOKUP(user_activity!A603,users_details!$A$1:$G$34,7,0) -> East Village | G36: Manhattan | H36: 42485 | I36: =TEXT(H36, "dddd") -> Monday | J36: =TEXT(H36, "mmmm") -> April | K36: 2.4200001 | L36: 2.4200001 | M36: 0 | N36: 0.23 | O36: 0.2 | P36: 1.99 | Q36: 0 | R36: 3 | S36: 5 | T36: 152 | U36: =R36+S36+T36 -> 160 | V36: 1280 | W36: 3588 | X36: =IF(W36=0,MEDIAN($W$2:$W$941),W36) -> 3588 | Y36: 1654 | Z36: {=_xlfn.IFS(OR(R36>66, S36>38), "High Engagement", OR(AND(R36>32, R36<=66), AND(S36>19, S36<=38)), "Medium-High Engagement", OR(AND(R36>4, R36<=32), AND(S36>6, S36<=19)),"Medium Engagement", TRUE, "Low Engagement" )} -> Low Engagement | AA36: =IF(W36>0, Y36/W36, 0) -> 0.46098105
A37: 2320127002 | B37: Mary Davis | C37: =VLOOKUP(user_activity!A626,users_details!$A$1:$G$34,5,0) -> 41 | D37: {=_xlfn.IFS( AND(C37>=18, C37<=25), "Emerging Adults", AND(C37>=26, C37<=35), "Young Adults", AND(C37>=36, C37<=45), "Midlife Adults", AND(C37>=46, C37<=55), "Mature Adults", C37>=56, "Older Adults", TRUE, "Age Not Mentioned")} -> Midlife Adults | E37: =VLOOKUP(user_activity!A626,users_details!$A$1:$G$34,6,0) -> East Harlem, Manhattan | F37: =VLOOKUP(user_activity!A626,users_details!$A$1:$G$34,7,0) -> East Harlem | G37: Manhattan | H37: 42482 | I37: =TEXT(H37, "dddd") -> Friday | J37: =TEXT(H37, "mmmm") -> April | K37: 3.76 | L37: 3.76 | M37: 0 | N37: 0 | O37: 0 | P37: 3.76 | Q37: 0 | R37: 0 | S37: 0 | T37: 266 | U37: =R37+S37+T37 -> 266 | V37: 1174 | W37: 5583 | X37: =IF(W37=0,MEDIAN($W$2:$W$941),W37) -> 5583 | Y37: 1851 | Z37: {=_xlfn.IFS(OR(R37>66, S37>38), "High Engagement", OR(AND(R37>32, R37<=66), AND(S37>19, S37<=38)), "Medium-High Engagement", OR(AND(R37>4, R37<=32), AND(S37>6, S37<=19)),"Medium Engagement", TRUE, "Low Engagement" )} -> Low Engagement | AA37: =IF(W37>0, Y37/W37, 0) -> 0.33154218
A38: 4319703577 | B38: James Smith | C38: =VLOOKUP(user_activity!A637,users_details!$A$1:$G$34,5,0) -> 41 | D38: {=_xlfn.IFS( AND(C38>=18, C38<=25), "Emerging Adults", AND(C38>=26, C38<=35), "Young Adults", AND(C38>=36, C38<=45), "Midlife Adults", AND(C38>=46, C38<=55), "Mature Adults", C38>=56, "Older Adults", TRUE, "Age Not Mentioned")} -> Midlife Adults | E38: =VLOOKUP(user_activity!A637,users_details!$A$1:$G$34,6,0) -> East Harlem, Manhattan | F38: =VLOOKUP(user_activity!A637,users_details!$A$1:$G$34,7,0) -> East Harlem | G38: Manhattan | H38: 42465 | I38: =TEXT(H38, "dddd") -> Tuesday | J38: =TEXT(H38, "mmmm") -> April | K38: 7.02 | L38: 7.02 | M38: 0 | N38: 0.58999997 | O38: 0.57999998 | P38: 5.8499999 | Q38: 0 | R38: 8 | S38: 13 | T38: 313 | U38: =R38+S38+T38 -> 334 | V38: 1106 | W38: 10429 | X38: =IF(W38=0,MEDIAN($W$2:$W$941),W38) -> 10429 | Y38: 2282 | Z38: {=_xlfn.IFS(OR(R38>66, S38>38), "High Engagement", OR(AND(R38>32, R38<=66), AND(S38>19, S38<=38)), "Medium-High Engagement", OR(AND(R38>4, R38<=32), AND(S38>6, S38<=19)),"Medium Engagement", TRUE, "Low Engagement" )} -> Medium Engagement | AA38: =IF(W38>0, Y38/W38, 0) -> 0.21881293
A39: 4319703577 | B39: James Smith | C39: =VLOOKUP(user_activity!A683,users_details!$A$1:$G$34,5,0) -> 49 | D39: {=_xlfn.IFS( AND(C39>=18, C39<=25), "Emerging Adults", AND(C39>=26, C39<=35), "Young Adults", AND(C39>=36, C39<=45), "Midlife Adults", AND(C39>=46, C39<=55), "Mature Adults", C39>=56, "Older Adults", TRUE, "Age Not Mentioned")} -> Mature Adults | E39: =VLOOKUP(user_activity!A683,users_details!$A$1:$G$34,6,0) -> Upper West Side, Manhattan | F39: =VLOOKUP(user_activity!A683,users_details!$A$1:$G$34,7,0) -> Upper West Side | G39: Manhattan | H39: 42374 | I39: =TEXT(H39, "dddd") -> Tuesday | J39: =TEXT(H39, "mmmm") -> January | K39: 0.83999997 | L39: 0.83999997 | M39: 0 | N39: 0 | O39: 0 | P39: 0.83999997 | Q39: 0 | R39: 0 | S39: 0 | T39: 67 | U39: =R39+S39+T39 -> 67 | V39: 836 | W39: 1251 | X39: =IF(W39=0,MEDIAN($W$2:$W$941),W39) -> 1251 | Y39: 1593 | Z39: {=_xlfn.IFS(OR(R39>66, S39>38), "High Engagement", OR(AND(R39>32, R39<=66), AND(S39>19, S39<=38)), "Medium-High Engagement", OR(AND(R39>4, R39<=32), AND(S39>6, S39<=19)),"Medium Engagement", TRUE, "Low Engagement" )} -> Low Engagement | AA39: =IF(W39>0, Y39/W39, 0) -> 1.2733813
A40: 2320127002 | B40: Mary Davis | C40: =VLOOKUP(user_activity!A688,users_details!$A$1:$G$34,5,0) -> 49 | D40: {=_xlfn.IFS( AND(C40>=18, C40<=25), "Emerging Adults", AND(C40>=26, C40<=35), "Young Adults", AND(C40>=36, C40<=45), "Midlife Adults", AND(C40>=46, C40<=55), "Mature Adults", C40>=56, "Older Adults", TRUE, "Age Not Mentioned")} -> Mature Adults | E40: =VLOOKUP(user_activity!A688,users_details!$A$1:$G$34,6,0) -> Upper West Side, Manhattan | F40: =VLOOKUP(user_activity!A688,users_details!$A$1:$G$34,7,0) -> Upper West Side | G40: Manhattan | H40: 42709 | I40: =TEXT(H40, "dddd") -> Monday | J40: =TEXT(H40, "mmmm") -> December | K40: 1.79 | L40: 1.79 | M40: 0 | N40: 0 | O40: 0 | P40: 1.79 | Q40: 0 | R40: 0 | S40: 0 | T40: 128 | U40: =R40+S40+T40 -> 128 | V40: 830 | W40: 2661 | X40: =IF(W40=0,MEDIAN($W$2:$W$941),W40) -> 2661 | Y40: 1125 | Z40: {=_xlfn.IFS(OR(R40>66, S40>38), "High Engagement", OR(AND(R40>32, R40<=66), AND(S40>19, S40<=38)), "Medium-High Engagement", OR(AND(R40>4, R40<=32), AND(S40>6, S40<=19)),"Medium Engagement", TRUE, "Low Engagement" )} -> Low Engagement | AA40: =IF(W40>0, Y40/W40, 0) -> 0.42277339
...

Sheet Sheet1
A1: UserID | B1: User Name | C1: Age | D1: Address | E1: Neighbourhood | F1: City | G1: Date | H1: Total_Distance | I1: Tracker_Distance | J1: Logged_Activities_Distance | K1: Very_Active_Distance | L1: Moderately_Active_Distance | M1: Light_Active_Distance | N1: Sedentary_Active_Distance | O1: Very_Active_Minutes | P1: Fairly_Active_Minutes | Q1: Lightly_Active_Minutes | R1: Sedentary_Minutes | S1: Steps | T1: Calories_Burned
A2: 1503960366 | B2: David Jones | C2: 38 | D2: East Harlem, Manhattan | E2: East Harlem | F2: Manhattan | G2: 42709 | H2: 0 | I2: 0 | J2: 0 | K2: 0 | L2: 0 | M2: 0 | N2: 0 | O2: 0 | P2: 0 | Q2: 0 | R2: 1440 | S2: 0 | T2: 0
A3: 6290855005 | B3: Mary Martinez | C3: 30 | D3: Midtown, Manhattan | E3: Midtown | F3: Manhattan | G3: 42483 | H3: 0 | I3: 0 | J3: 0 | K3: 0 | L3: 0 | M3: 0 | N3: 0 | O3: 33 | P3: 0 | Q3: 0 | R3: 1407 | S3: 0 | T3: 2664
A4: 6117666160 | B4: Robert Johnson | C4: 53 | D4: Williamsburg, Brooklyn | E4: Williamsburg | F4: Brooklyn | G4: 42473 | H4: 0 | I4: 0 | J4: 0 | K4: 0 | L4: 0 | M4: 0 | N4: 0 | O4: 0 | P4: 0 | Q4: 0 | R4: 1440 | S4: 0 | T4: 1496
A5: 6117666160 | B5: Robert Johnson | C5: 53 | D5: Williamsburg, Brooklyn | E5: Williamsburg | F5: Brooklyn | G5: 42474 | H5: 0 | I5: 0 | J5: 0 | K5: 0 | L5: 0 | M5: 0 | N5: 0 | O5: 0 | P5: 0 | Q5: 0 | R5: 1440 | S5: 0 | T5: 1496
A6: 4020332650 | B6: David Smith | C6: 54 | D6: Crown Heights, Brooklyn | E6: Crown Heights | F6: Brooklyn | G6: 42481 | H6: 0 | I6: 0 | J6: 0 | K6: 0 | L6: 0 | M6: 0 | N6: 0 | O6: 0 | P6: 0 | Q6: 0 | R6: 1440 | S6: 0 | T6: 1980
A7: 1844505072 | B7: Linda Rodriguez | C7: 53 | D7: Harlem, Manhattan | E7: Harlem | F7: Manhattan | G7: 42648 | H7: 0 | I7: 0 | J7: 0 | K7: 0 | L7: 0 | M7: 0 | N7: 0 | O7: 0 | P7: 0 | Q7: 0 | R7: 1440 | S7: 0 | T7: 1347
A8: 1927972279 | B8: Michael Brown | C8: 29 | D8: Crown Heights, Brooklyn | E8: Crown Heights | F8: Brooklyn | G8: 42490 | H8: 0 | I8: 0 | J8: 0 | K8: 0 | L8: 0 | M8: 0 | N8: 0 | O8: 0 | P8: 0 | Q8: 0 | R8: 1440 | S8: 0 | T8: 2064
A9: 4020332650 | B9: David Smith | C9: 54 | D9: Crown Heights, Brooklyn | E9: Crown Heights | F9: Brooklyn | G9: 42489 | H9: 0 | I9: 0 | J9: 0 | K9: 0 | L9: 0 | M9: 0 | N9: 0 | O9: 0 | P9: 0 | Q9: 0 | R9: 1440 | S9: 0 | T9: 1980
A10: 4020332650 | B10: David Smith | C10: 54 | D10: Crown Heights, Brooklyn | E10: Crown Heights | F10: Brooklyn | G10: 42483 | H10: 0 | I10: 0 | J10: 0 | K10: 0 | L10: 0 | M10: 0 | N10: 0 | O10: 0 | P10: 0 | Q10: 0 | R10: 1440 | S10: 0 | T10: 1980
A11: 6775888955 | B11: David Davis | C11: 45 | D11: Harlem, Manhattan | E11: Harlem | F11: Manhattan | G11: 42495 | H11: 0 | I11: 0 | J11: 0 | K11: 0 | L11: 0 | M11: 0 | N11: 0 | O11: 0 | P11: 0 | Q11: 0 | R11: 1440 | S11: 0 | T11: 1841
A12: 4020332650 | B12: David Smith | C12: 54 | D12: Crown Heights, Brooklyn | E12: Crown Heights | F12: Brooklyn | G12: 42487 | H12: 0 | I12: 0 | J12: 0 | K12: 0 | L12: 0 | M12: 0 | N12: 0 | O12: 0 | P12: 0 | Q12: 0 | R12: 1440 | S12: 0 | T12: 1980
A13: 1844505072 | B13: Linda Rodriguez | C13: 53 | D13: Harlem, Manhattan | E13: Harlem | F13: Manhattan | G13: 42587 | H13: 0 | I13: 0 | J13: 0 | K13: 0 | L13: 0 | M13: 0 | N13: 0 | O13: 0 | P13: 0 | Q13: 0 | R13: 1440 | S13: 0 | T13: 1347
... A78: 1844505072 | B78: Linda Rodriguez | C78: 53 | D78: Harlem, Manhattan | E78: Harlem | F78: Manhattan | G78: 42486 | H78: 0 | I78: 0 | J78: 0 | K78: 0 | L78: 0 | M78: 0 | N78: 0 | O78: 0 | P78: 0 | Q78: 0 | R78: 1440 | S78: 0 | T78: 1347
